Workbook

Sheet Hoja1
I3: FECHA DE ELABORACIÓN: | K3: 31 de agosto 2026
I4: EXPEDIENTE No.: | K4: REPORTE_001
B6: CON FUNDAMENTO EN LOS ARITUCULOS 3 FRACCION IV DE LA LEY CONTRATACION PUBLICA DEL ESTADO DE MEXICOY MUNICIPIOS , 17 Y 18 DE SU REGLAMENTO LA DIRECCION DE ADMINISTRACIÓN, A TRAVES DE LA UNIDAD DE ADQUISICIONES Y RECURSOS MATERIALES, DIO INICIO AL ESTUDIO DE MERCADO PARA LA (ADQUISICION O PRESTACION DEL SERVICIO), A FIN DE VERIFICAR LA EXISTENCIA DE (BIEN O SERVICIO), ASI COMO DE (PROVEEDORES O PRESTADORES DE SERVICIOS) A NIVEL (LOCAL, NACIONAL O INTERNACIONAL), PARA ASEGURAR LAS MEJORES CONDICIONES PARA EL MUNICIPIO DE ACAMBAY DE RUIZ CASTAÑEDA EN CUANTO A PRECIO, CALIDAD, OPORTUNIDAD, CANTIDAD, Y DEMAS CARACTERISTICAS SOLICITADAS.
B7: CABE MENCIONAR QUE DICHA (ADQUISICION, O CONTRATACION DEL SERVICIO) SE ENCUENTRA CONSIDERADO EN EL PROGRAMA ANUAL DE ADQUISICIONES Y SERVICIOS 2026
B9: ÁREA ADMINISTRATIVA USUARIA | D9: E00 311 COOR. DESARROLLO COMUNITARIO (DESAYUNOS FRIOS) | H9: CLAVE PROGRAMATICA: | K9: 205060301
B10: PARTIDA PRESUPUESTAL | D10: 1122 SERVICIO DE MONITOREO Y SEGUIMIENTO
B11: OBJETO DE LA CONTRATACIÓN Y/O ADQUISICIÓN: | D11: REALIZAR SERVICIOS DE SEGUIMIENTO
B13: FUENTES CONSULTADAS CON LA FINALIDAD DE DAR CUMPLIMIENTO A LO ESTABLECIDO EN LOS ARTICULOS 17 Y 18 DEL REGLAMENTO DE LA LEY CONTRATACION PUBLICA DEL ESTADO DE MEXICOY MUNICIPIOS, EL DEPARTAMENTO DE ADQUISICIONES REALIZO EL ESTUDIO DE MERCADO PARA DETERMINAR LA EXISTENCIA DE (BIENES O SERVICIOS) Y (PROVEEDORES O PRESTADORES DE SERVICIOS), ASI COMO CONOCER EL PRECIO QUE PREVALECE EN EL MERCADO, ENVIANDO INVITACIONES PARA COTIZAR A:
B15: N.P | C15: PERSONA FISICA O JURIDICO COLECTIVA CONSULTADA | G15: NUMERO TELEFONICO DE CONTACTO | J15: SE ENCUENTRA REGISTRADA EN EL PADRON DE PROVEEDORES DEL MUNICIPIO
B16: 1 | C16: Gabriel Lopez Crisostomo | G16: 7122893019 | J16: SI
B17: 2 | C17: Santiago Lopez Cruz | G17: 8120381738 | J17: SI
B18: 3
B20: DE CONFORMIDAD CON LO ESTABLECIDO EN LA LEY DE CONTRATACION PUBLICA DEL ESTADO DE MEXICO Y MUNICIPIOS Y SU REGLAMENTO, SE LLEVA A CABO LA ELABORACION DE ESTUDIO DE MERCADO, CON LA INFORMACION OBTENIDA DE LAS FUENTES ANTERIORES MENCIONADAS; DETERMINANDO LO SIGUIENTE:
B21: A. CANTIDAD DE LOS (PROVEEDORES O PRESTADORES DE SERVICIO) CONSULTADOS, LOS SIGUIENTES COTIZARON LOS (BIENES O SERVICIOS) SOLICITADOS:
B23: N.P | C23: PERSONA FISICA O JURIDICO COLECTIVA CONSULTADA | G23: NUMERO TELEFONICO DE CONTACTO | J23: CUMPLE
B24: 1 | C24: Gabriel Lopez Crisostomo | G24: 7122893019 | J24: SI
B25: 2 | C25: Santiago Lopez Cruz | G25: 8120381738 | J25: NO
B26: 3
B28: B. CALIDAD DE LOS (PROVEEDORES O PRESTADORES DE SERVICIO) CONSULTADOS, LOS SIGUIENTES CUMPLEN CON LAS ESPECIFICACIONES TECNICAS DE LOS (BIENES O SERVICIOS) SOLICITADOS:
B29: N.P | C29: PERSONA FISICA O JURIDICO COLECTIVA CONSULTADA | G29: NUMERO TELEFONICO DE CONTACTO | J29: CUMPLE
B30: 1 | C30: Gabriel Lopez Crisostomo | G30: 7122893019 | J30: SI
B31: 2 | C31: Santiago Lopez Cruz | G31: 8120381738 | J31: SI
B32: 3
B34: C. OPORTUNIDAD DE LOS (PROVEEDORES O PRESTADORES DE SERVICIO) CONSULTADOS, LOS SIGUIENTES CUMPLEN CON LAS ESPECIFICACIONES ADMINISTRATIVAS Y PARAMETROS DE REFERENCIA, RELATIVOS A LOS (BIENES O SERVICIOS) SOLICITADOS:
B35: N.P | C35: PERSONA FISICA O JURIDICO COLECTIVA CONSULTADA | G35: NUMERO TELEFONICO DE CONTACTO | J35: CUMPLE
B36: 1 | C36: Gabriel Lopez Crisostomo | G36: 7122893019 | J36: SI
B37: 2 | C37: Santiago Lopez Cruz | G37: 8120381738 | J37: NO
B38: 3
B40: ALCANCE: DE ACUERDO CON LAS COTIZACIONES OBTENIDAS, PARA DETERMINAR LA EXISTENCIA DEL (BIEN O SERVICIO) Y DE (PROVEEDORES O PRESTADORES DE SERVICIOS), ASI COMO CONOCER EL PRECIO QUE PREVALECE EN EL MERCADO, SE PRESENTA EL SIGUIENTE ESTUDIO DE MERCADO:
D42: FECHA | F42: COTIZACIÓN 1 | H42: COTIZACIÓN 2 | J42: COTIZACION 3
F43: =C24 -> Gabriel Lopez Crisostomo | H43: =C25 -> Santiago Lopez Cruz
B45: N.P | C45: DESCRIPCION | D45: UNIDAD DE MEDIDA | E45: CANTIDAD | F45: PRECIO UNITARIO | G45: IMPORTE | H45: PRECIO UNITARIO | I45: IMPORTE | J45: PRECIO UNITARIO | K45: IMPORTE | L45: PRECIO PROMEDIO DE REFERENCIA
B46: 1 | C46: SERVICIO DE EXTRACCION | D46: SERVICIO | E46: 3 | F46: 300 | G46: 900 | H46: 100 | I46: 300 | L46: 200
B47: 2 | C47: SERVICIO DE MANEJO | D47: SERVICIO | E47: 3 | F47: 200 | G47: 600 | H47: 200 | I47: 600 | L47: 200
B48: 3 | C48: SERVICIO DE CONSUMO | D48: SERVICIO | E48: 2 | F48: 150 | G48: 300 | H48: 200 | I48: 400 | L48: 175
B49: 4 | G49: =F49*E49 -> 0 | I49: =H49*E49 -> 0 | L49: =(F49+H49+J49)/2 -> 0
F50: SUBTOTAL | G50: 1800 | H50: SUBTOTAL | I50: 1300 | J50: SUBTOTAL | L50: =(G50+I50)/2 -> 1550
F51: I.V.A. | G51: 288 | I51: 208
F52: TOTAL | G52: 2088 | H52: TOTAL | I52: 1508 | J52: TOTAL | L52: 1798
B54: N.P | C54: CONDICIONES COMERCIALES | G54: CUMPLEN CON LAS CONDICIONES COMERCIALES (SI/NO)
...

Sheet Hoja2
B8: Toluca a | D8: 7 de agosto de 2026.
A10: SISTEMA MUNICIPAL DIF DE SAN FELIPE DEL PROGRESO
A11: MTRA. YARASHED MARTÍNEZ SÁNCHEZ
A12: COORDINADORA DE ADMINISTRACIÓN
A13: PRESENTE
A14: POR MEDIO DEL PRESENTE RECIBA UN CORDIAL SALUDO, ASÍ MISMO ENVIAMOS LA SIGUIENTE:
A16: COTIZACIÓN
A18: UNIDAD DE MEDIDA | B18: CONCEPTO | C18: CANTIDAD | D18: COSTO UNITARIO | E18: IMPORTE
B19: =Hoja1!C46 -> SERVICIO DE EXTRACCION | D19: =Hoja1!F46 -> 300 | E19: =C19*D19 -> 0
B20: =Hoja1!C47 -> SERVICIO DE MANEJO | D20: =Hoja1!F47 -> 200 | E20: =C20*D20 -> 0
B21: =Hoja1!C48 -> SERVICIO DE CONSUMO | D21: =Hoja1!F48 -> 150 | E21: =C21*D21 -> 0
B22: =Hoja1!C49 -> 0 | D22: =Hoja1!F49 -> 0 | E22: =C22*D22 -> 0
A23: IMPORTE CON LETRA: | D23: SUBTOTAL | E23: =SUM(E19:E22) -> 0
A24: CINCO MIL DOSCIENTOS VEINTE PESOS 00/100 M.N. | D24: I.V.A.
D25: TOTAL | E25: =SUM(E23:E24) -> 0
A27: CONDICIONES COMERCIALES:
A29: LUGAR DE LA PRESTACIÓN DEL SERVICIO O ENTREGA DE BIENES:
A31: FORMA DE PAGO:
A33: PLAZO DE ENTREGA DE LOS BIENES Y/O SERVICIOS:
A34: DENTRO DE LOS 30 DIAS HABILES POSTERIORES A LA CONFIRMACIÓN DEL PEDIDO O FIRMA DEL CONTRATO.
A35: VIGENCIA DE LA COTIZACIÓN:
A36: 45 DIAS POSTERIORES A SU EMISIÓN
A38: SIN MAS POR EL MOMENTO Y EN ESPERA DE VERNOS FAVORECIDO QUEDO DE USTED.
B40: ATENTAMENTE
